Workbook

Sheet Main
C2: Main: | H2: Founded | I2: 1963
C3: Monopoly on Cyprus cement production | H3: Sector | I3: Constuction Materials | K3: VCW
C4: Fast growing economy in EU (3%+ p.a) | H4: Product | I4: Cement
C5: Working on energy independence (via solar) | K5: Price | L5: 5
C6: Improving efficiency (15% gp to 33% in 4y) | K6: Shares | L6: 71940
K7: MC | L7: =L5*L6 -> 359700
K8: Cash | L8: =Model!J59 -> 42184
K9: Debt | L9: =Model!J73 -> 2198
C10: Subsidiary: | K10: EV | L10: =L7-L8+L9 -> 319714
C12: Enerco - Energy Recovery Limited (50%) | G12: Waste Managment | K12: P/B | L12: =L7/Model!J65 -> 1.311754
K13: P/S | L13: =L7/Model!J7 -> 2.3547511
K14: P/E | L14: =L7/Model!J28 -> 10.124694
K15: Book | L15: =L7/Model!J81 -> 1.311754
C17: Notes:
C18: Operates in a high growth economy, lower taxes than most EU countries
C19: Has essentially a monopoly on cement in CY, very diffcult for a new player to get into this market ($100M+ Capex and regulatory issues)
C20: Great balance sheet currently, could face major headwinds and survive
C21: Has the infrastucture to expand due to their integrated port (has still a high depency on the domestic market, 88% 2025)
C22: Could suffer due to higher energy cost due to war in Iran
C23: Stock is difficult to buy on platforms and if the investment is based on DY, how would you get those returns?
C24: Fairly valued, would be a good dividend stock to park money in
C25: Not a buying recommendation

Sheet Model
A1: in thousands | C1: 2018 | D1: 2019 | E1: 2020 | F1: 2021 | G1: 2022 | H1: 2023 | I1: 2024 | J1: 2025 | K1: =J1+1 -> 2026 | L1: =K1+1 -> 2027 | M1: =L1+1 -> 2028 | N1: =M1+1 -> 2029 | O1: =N1+1 -> 2030 | P1: =O1+1 -> 2031 | Q1: =P1+1 -> 2032 | R1: =Q1+1 -> 2033 | ... AE1: =AD1+1 -> 2046
A3: Cement | G3: 140370 | H3: 158196 | I3: 136038 | J3: 151493
A4: Electricity | G4: 2193 | H4: 2220 | I4: 1613 | J4: 1127
A5: Other | G5: 98 | H5: 116 | I5: 132 | J5: 135
A7: Revenue | C7: 97926 | D7: 100984 | E7: 105661 | F7: 101419 | G7: =SUM(G3:G5) -> 142661 | H7: =SUM(H3:H5) -> 160532 | I7: =SUM(I3:I5) -> 137783 | J7: =SUM(J3:J5) -> 152755 | K7: =J7*(1+K8) -> 160392.75 | L7: =K7*(1+L8) -> 168412.39 | M7: =L7*(1+M8) -> 176833.01 | N7: =M7*(1+N8) -> 185674.66 | O7: =N7*(1+O8) -> 194958.39 | P7: =O7*(1+P8) -> 204706.31 | Q7: =P7*(1+Q8) -> 214941.63 | R7: =Q7*(1+R8) -> 225688.71 | ... AE7: =AD7*(1+AE8) -> 248821.8
A8: % growth | D8: =(D7-C7)/C7 -> 0.031227662 | E8: =(E7-D7)/D7 -> 0.046314268 | F8: =(F7-E7)/E7 -> -0.040147263 | G8: =(G7-F7)/F7 -> 0.40664964 | H8: =(H7-G7)/G7 -> 0.12526899 | I8: =(I7-H7)/H7 -> -0.14171006 | J8: =(J7-I7)/I7 -> 0.10866362 | K8: 0.05 | L8: 0.05 | M8: 0.05 | N8: 0.05 | O8: 0.05 | P8: 0.05 | Q8: 0.05 | R8: 0.05 | S8: 0.05 | T8: 0.05
A9: COGS | C9: 70944 | D9: 70093 | E9: 77192 | F9: 73777 | G9: 119381 | H9: 119045 | I9: 95286 | J9: 102450
A11: Gross | C11: =C7-C9 -> 26982 | D11: =D7-D9 -> 30891 | E11: =E7-E9 -> 28469 | F11: =F7-F9 -> 27642 | G11: =G7-G9 -> 23280 | H11: =H7-H9 -> 41487 | I11: =I7-I9 -> 42497 | J11: =J7-J9 -> 50305
A12: % gross | C12: =C11/C7 -> 0.27553459 | D12: =D11/D7 -> 0.30589994 | E12: =E11/E7 -> 0.26943716 | F12: =F11/F7 -> 0.27255248 | G12: =G11/G7 -> 0.16318405 | H12: =H11/H7 -> 0.25843446 | I12: =I11/I7 -> 0.30843428 | J12: =J11/J7 -> 0.32931819
A14: Other Income | E14: 1605 | F14: 1357 | G14: 2535 | H14: 2386 | I14: 2482 | J14: 2692
A15: Distribution | E15: -5413 | F15: -4879 | G15: -5758 | H15: -6296 | I15: -3908 | J15: -3779
A16: Admin | E16: -3899 | F16: -4169 | G16: -4002 | H16: -4782 | I16: -4959 | J16: -5576
A17: Fines | I17: -5071 | J17: 0
A18: Other Expenses | E18: -1915 | F18: -1442 | G18: -1499 | H18: -1526 | I18: -1599 | J18: -1066
A19: EBIT | E19: =SUM(E11:E18) -> 18847.269 | F19: =SUM(F11:F18) -> 18509.273 | G19: =SUM(G11:G18) -> 14556.163 | H19: =SUM(H11:H18) -> 31269.258 | I19: =SUM(I11:I18) -> 29442.308 | J19: =SUM(J11:J18) -> 42576.329
A21: Interest Income | E21: 9 | F21: 112 | G21: 311 | H21: 330 | I21: 401 | J21: 275
A22: Interest Expense | E22: -115 | F22: -286 | G22: -531 | H22: -435 | I22: -509 | J22: -218
A23: Investing | F23: -45 | G23: 83 | H23: -29 | I23: 96 | J23: 21
A24: Joint Venture | E24: 647 | F24: 727 | G24: 603 | H24: 854 | I24: 985 | J24: 1349
A25: Profit Before Tax | E25: =E19+SUM(E21:E24) -> 19388.269 | F25: =F19+SUM(F21:F24) -> 19017.273 | G25: =G19+SUM(G21:G24) -> 15022.163 | H25: =H19+SUM(H21:H24) -> 31989.258 | I25: =I19+SUM(I21:I24) -> 30415.308 | J25: =J19+SUM(J21:J24) -> 44003.329
A27: Tax | G27: =G28-G25 -> -2304.1632 | H27: =H28-H25 -> -4149.2584 | I27: =I28-I25 -> -4534.3084 | J27: =J28-J25 -> -8476.3293
A28: Net Income | C28: 15736 | D28: 20349 | E28: 16681 | F28: 17441 | G28: 12718 | H28: 27840 | I28: 25881 | J28: 35527
A29: % net | C29: =C28/C7 -> 0.16069277 | D29: =D28/D7 -> 0.20150717 | E29: =E28/E7 -> 0.15787282 | F29: =F28/F7 -> 0.17196975 | G29: =G28/G7 -> 0.089148401 | H29: =H28/H7 -> 0.17342337 | I29: =I28/I7 -> 0.18783885 | J29: =J28/J7 -> 0.23257504 | K29: 0.2 | L29: 0.2 | M29: 0.2 | N29: 0.2 | O29: 0.2 | P29: 0.2 | Q29: 0.2 | R29: 0.2 | S29: 0.2 | T29: 0.2 | U29: 0.2 | V29: 0.2 | W29: 0.2 | X29: 0.2 | Y29: 0.2 | Z29: 0.2 | AA29: 0.2 | AB29: 0.2 | AC29: 0.2 | AD29: 0.2 | AE29: 0.2
A31: Shares | C31: 71940 | D31: 71940 | E31: 71940 | F31: 71940 | G31: 71940 | H31: 71940 | I31: 71940 | J31: 71940 | K31: 71940 | L31: 71940 | M31: 71940 | N31: 71940 | O31: 71940 | P31: 71940 | Q31: 71940 | R31: 71940 | S31: 71940 | T31: 71940 | U31: 71940 | V31: 71940 | W31: 71940 | X31: 71940 | Y31: 71940 | Z31: 71940 | AA31: 71940 | AB31: 71940 | AC31: 71940 | AD31: 71940 | AE31: 71940
A32: EPS | C32: =C28/C31 -> 0.21873784 | D32: =D28/D31 -> 0.28286072 | E32: =E28/E31 -> 0.23187378 | F32: =F28/F31 -> 0.24243814 | G32: =G28/G31 -> 0.17678621 | H32: =H28/H31 -> 0.38698916 | I32: =I28/I31 -> 0.35975813 | J32: =J28/J31 -> 0.49384209 | K32: =(K7*K29)/K31 -> 0.44590701 | L32: =(L7*L29)/L31 -> 0.46820236 | M32: =(M7*M29)/M31 -> 0.49161247 | N32: =(N7*N29)/N31 -> 0.5161931 | O32: =(O7*O29)/O31 -> 0.54200275 | P32: =(P7*P29)/P31 -> 0.56910289 | Q32: =(Q7*Q29)/Q31 -> 0.59755803 | R32: =(R7*R29)/R31 -> 0.62743594 | ... AE32: =(AE7*AE29)/AE31 -> 0.69174812 | AF32: =AE32*(1+$M$43) -> 0.68483064 | AG32: =AF32*(1+$M$43) -> 0.67798233 | AH32: =AG32*(1+$M$43) -> 0.67120251 | AI32: =AH32*(1+$M$43) -> 0.66449048 | AJ32: =AI32*(1+$M$43) -> 0.65784558 | AK32: =AJ32*(1+$M$43) -> 0.65126712 | AL32: =AK32*(1+$M$43) -> 0.64475445 | AM32: =AL32*(1+$M$43) -> 0.63830691 | ... CQ32: =CP32*(1+$M$43) -> 0.36358038
A33: Dividend | E33: =0.08+0.06 -> 0.14 | F33: =0.08+0.13 -> 0.21 | G33: =0.13+0.06 -> 0.19 | H33: =0.13+0.08 -> 0.21 | I33: =0.17+0.12 -> 0.29 | J33: 0.38 | K33: =K32*K36 -> 0.3567256 | L33: =L32*L36 -> 0.37456188 | M33: =M32*M36 -> 0.39328998 | N33: =N32*N36 -> 0.41295448 | O33: =O32*O36 -> 0.4336022 | P33: =P32*P36 -> 0.45528231 | Q33: =Q32*Q36 -> 0.47804643 | R33: =R32*R36 -> 0.50194875 | ... AE33: =AE32*AE36 -> 0.5533985
A34: Dividend (reinvested at yield) | K34: =K33*(1+K35)*(1+L35)*(1+M35)*(1+N35)*(1+O35) -> 0.50032611 | L34: =L33*(1+L35)*(1+M35)*(1+N35)*(1+O35)*(1+P35) -> 0.49097422 | M34: =M33*(1+M35)*(1+N35)*(1+O35)*(1+P35)*(1+Q35) -> 0.48179714 | N34: =N33*(1+N35)*(1+O35)*(1+P35)*(1+Q35)*(1+R35) -> 0.47279158 | O34: =O33*(1+O35)*(1+P35)*(1+Q35)*(1+R35)*(1+S35) -> 0.46395436 | P34: =P33*(1+P35)*(1+Q35)*(1+R35)*(1+S35)*(1+T35) -> 0.45528231 | Q34: =Q33*(1+Q35)*(1+R35)*(1+S35)*(1+T35)*(1+U35) -> 0.47804643 | R34: =R33*(1+R35)*(1+S35)*(1+T35)*(1+U35)*(1+V35) -> 0.50194875 | ... AE34: =AE33*(1+AE35)*(1+AF35)*(1+AG35)*(1+AH35)*(1+AI35) -> 0.5533985
A35: % yield | K35: 0.07 | L35: 0.07 | M35: 0.07 | N35: 0.07 | O35: 0.07
A36: % payout | E36: =E33/E32 -> 0.60377675 | F36: =F33/F32 -> 0.86620033 | G36: =G33/G32 -> 1.0747445 | H36: =H33/H32 -> 0.54265086 | I36: =I33/I32 -> 0.80609714 | J36: =J33/J32 -> 0.76947674 | K36: 0.8 | L36: 0.8 | M36: 0.8 | N36: 0.8 | O36: 0.8 | P36: 0.8 | Q36: 0.8 | R36: 0.8 | S36: 0.8 | T36: 0.8 | U36: 0.8 | V36: 0.8 | W36: 0.8 | X36: 0.8 | Y36: 0.8 | Z36: 0.8 | AA36: 0.8 | AB36: 0.8 | AC36: 0.8 | AD36: 0.8 | AE36: 0.8
A39: D&A | E39: 13939 | F39: 14258 | G39: 15253 | H39: 14255 | I39: 14251 | J39: 14196
A40: ΔWC | E40: =-608+5217-1046 -> 3563 | F40: =972-16366-502 -> -15896 | G40: =-5648-4154+5421-300 -> -4681 | H40: =1766-1100-1303 -> -637 | I40: =890-587-2317 -> -2014 | J40: =-1416+5512+465 -> 4561
A41: Capex | E41: -10886 | F41: -9925 | G41: -10490 | H41: -5934 | I41: -6876 | J41: -9966
A42: FCF | E42: =E28+SUM(E39:E41) -> 23297 | F42: =F28+SUM(F39:F41) -> 5878 | G42: =G28+SUM(G39:G41) -> 12800 | H42: =H28+SUM(H39:H41) -> 35524 | I42: =I28+SUM(I39:I41) -> 31242 | J42: =J28+SUM(J39:J41) -> 44318 | L42: DCF | P42: Comparables | S42: Assumptions
A43: % fcf | E43: =E42/E7 -> 0.22048816 | F43: =F42/F7 -> 0.057957582 | G43: =G42/G7 -> 0.08972319 | H43: =H42/H7 -> 0.22128921 | I43: =I42/I7 -> 0.22674786 | J43: =J42/J7 -> 0.29012471 | L43: Maturity | M43: -0.01 | P43: P/E | Q43: 10
L44: Discount | M44: =0.0348+0.0578 -> 0.0926 | P44: Price 2030 | Q44: =Q43*O32 -> 5.4200275
L45: NPV | M45: =NPV(M44,K32:CQ32) -> 6.3901829 | P45: Dividends inv. | Q45: =SUM(K34:O34) -> 2.4098434 | S45: Company will grow at very small stable rate (under the 8% of the last 7y)
L46: Price | M46: 5 | P46: Current Price | Q46: 5 | S46: P/E remains at 10 in 5 years (10-15 ratio average in EU)
L47: Upside | M47: =M45/M46-1 -> 0.27803657 | P47: Upside | Q47: =Q44/Q46-1 -> 0.084005505 | S47: Dividends continue and payout at current rate (has been since 2014)
A48: PP&E | E48: 226107 | F48: 221837 | G48: 213249 | H48: 200381 | I48: 193640 | J48: 189320 | L48: w/dividends | M48: =(Q45+M45)/M46 -> 1.7600053 | P48: w/dividends | Q48: =(Q44+Q45)/Q46-1 -> 0.56597419 | S48: Reinvesting the dividends at a 7% yield
A49: Intangible | E49: 12363 | F49: 12332 | G49: 12338 | H49: 12336 | I49: 12344 | J49: 12342 | L49: p.a | M49: =((M45+Q45)/M46)^(1/5)-1 -> 0.11970287 | P49: p.a | Q49: =((Q44+Q45)/Q46)^(1/5)-1 -> 0.093847856 | S49: Fairly conservative, although without taxation
...
